Workbook

Sheet Hoy
A1: ¿Qué conviene traer? · 30/10/2026
A2: eBay: vendedor en EE.UU., ≥ 98 % de feedback, nuevo sin open box. Marketplace y Tiendas: el precio más bajo que cuenta en Cochabamba. Costo puesto con el courier más barato, según la hoja Supuestos.
A4: Producto | B4: Tipo | C4: Link del producto | D4: eBay nuevo USD | E4: Envío EE.UU. USD | F4: eBay usado USD | G4: Marketplace Bs | H4: Tiendas Bs | I4: Dólar BCB | J4: Dólar paralelo | K4: Peso g | L4: Courier /u USD | M4: Costo puesto Bs | N4: Mejor local Bs | O4: Ganancia /u Bs | P4: Margen | Q4: Estado
A5: SSD NVMe 2TB | B5: SSD | C5: ver en eBay | D5: 185 | E5: 0 | F5: 154.99 | G5: 3100 | H5: 4060 | I5: =INDEX(Dólar!$B:$B,MATCH(MAX(Dólar!$A:$A),Dólar!$A:$A,0)) | J5: =INDEX(Dólar!$E:$E,MATCH(MAX(Dólar!$A:$A),Dólar!$A:$A,0)) | K5: 80 | L5: =IF(D5="","",MIN(MAX(Supuestos!$B$5,CEILING((K5*Supuestos!$B$3+Supuestos!$B$7)/1000,Supuestos!$B$6))*Supuestos!$B$4/Supuestos!$B$3,Supuestos!$B$8+D5*Supuestos!$B$9)) | M5: =IF(D5="","",(D5+E5+L5+(D5+E5)*Supuestos!$B$10)*Supuestos!$B$11) | N5: =IF(COUNT(G5:H5)=0,"",MIN(G5:H5)) | O5: =IF(OR(M5="",N5=""),"",N5-M5) | P5: =IF(O5="","",O5/N5) | Q5: =IF(P5="",IF(AND(D5="",N5=""),"Sin datos",IF(D5="","Sin precio eBay","Sin precio local")),IF(P5>=Supuestos!$B$12,"Conviene",IF(P5>=Supuestos!$B$13,"Justo","No conviene")))
A6: Intel Core Ultra 7 265K | B6: CPU | C6: ver en eBay | D6: 248 | E6: 0 | F6: 249.99 | H6: 3950 | I6: =INDEX(Dólar!$B:$B,MATCH(MAX(Dólar!$A:$A),Dólar!$A:$A,0)) | J6: =INDEX(Dólar!$E:$E,MATCH(MAX(Dólar!$A:$A),Dólar!$A:$A,0)) | K6: 300 | L6: =IF(D6="","",MIN(MAX(Supuestos!$B$5,CEILING((K6*Supuestos!$B$3+Supuestos!$B$7)/1000,Supuestos!$B$6))*Supuestos!$B$4/Supuestos!$B$3,Supuestos!$B$8+D6*Supuestos!$B$9)) | M6: =IF(D6="","",(D6+E6+L6+(D6+E6)*Supuestos!$B$10)*Supuestos!$B$11) | N6: =IF(COUNT(G6:H6)=0,"",MIN(G6:H6)) | O6: =IF(OR(M6="",N6=""),"",N6-M6) | P6: =IF(O6="","",O6/N6) | Q6: =IF(P6="",IF(AND(D6="",N6=""),"Sin datos",IF(D6="","Sin precio eBay","Sin precio local")),IF(P6>=Supuestos!$B$12,"Conviene",IF(P6>=Supuestos!$B$13,"Justo","No conviene")))
A7: Intel Core i5-12400F | B7: CPU | C7: ver en eBay | D7: 140 | E7: 0 | F7: 119.99 | G7: 2350 | H7: 2260 | I7: =INDEX(Dólar!$B:$B,MATCH(MAX(Dólar!$A:$A),Dólar!$A:$A,0)) | J7: =INDEX(Dólar!$E:$E,MATCH(MAX(Dólar!$A:$A),Dólar!$A:$A,0)) | K7: 250 | L7: =IF(D7="","",MIN(MAX(Supuestos!$B$5,CEILING((K7*Supuestos!$B$3+Supuestos!$B$7)/1000,Supuestos!$B$6))*Supuestos!$B$4/Supuestos!$B$3,Supuestos!$B$8+D7*Supuestos!$B$9)) | M7: =IF(D7="","",(D7+E7+L7+(D7+E7)*Supuestos!$B$10)*Supuestos!$B$11) | N7: =IF(COUNT(G7:H7)=0,"",MIN(G7:H7)) | O7: =IF(OR(M7="",N7=""),"",N7-M7) | P7: =IF(O7="","",O7/N7) | Q7: =IF(P7="",IF(AND(D7="",N7=""),"Sin datos",IF(D7="","Sin precio eBay","Sin precio local")),IF(P7>=Supuestos!$B$12,"Conviene",IF(P7>=Supuestos!$B$13,"Justo","No conviene")))
A8: Ryzen 7 7800X3D | B8: CPU | C8: ver en eBay | D8: 329 | E8: 0 | F8: 265 | G8: 4800 | H8: 4760 | I8: =INDEX(Dólar!$B:$B,MATCH(MAX(Dólar!$A:$A),Dólar!$A:$A,0)) | J8: =INDEX(Dólar!$E:$E,MATCH(MAX(Dólar!$A:$A),Dólar!$A:$A,0)) | K8: 350 | L8: =IF(D8="","",MIN(MAX(Supuestos!$B$5,CEILING((K8*Supuestos!$B$3+Supuestos!$B$7)/1000,Supuestos!$B$6))*Supuestos!$B$4/Supuestos!$B$3,Supuestos!$B$8+D8*Supuestos!$B$9)) | M8: =IF(D8="","",(D8+E8+L8+(D8+E8)*Supuestos!$B$10)*Supuestos!$B$11) | N8: =IF(COUNT(G8:H8)=0,"",MIN(G8:H8)) | O8: =IF(OR(M8="",N8=""),"",N8-M8) | P8: =IF(O8="","",O8/N8) | Q8: =IF(P8="",IF(AND(D8="",N8=""),"Sin datos",IF(D8="","Sin precio eBay","Sin precio local")),IF(P8>=Supuestos!$B$12,"Conviene",IF(P8>=Supuestos!$B$13,"Justo","No conviene")))
A9: Intel Core i5-14400F | B9: CPU | C9: ver en eBay | D9: 164.49 | E9: 0 | F9: 130 | H9: 2384 | I9: =INDEX(Dólar!$B:$B,MATCH(MAX(Dólar!$A:$A),Dólar!$A:$A,0)) | J9: =INDEX(Dólar!$E:$E,MATCH(MAX(Dólar!$A:$A),Dólar!$A:$A,0)) | K9: 250 | L9: =IF(D9="","",MIN(MAX(Supuestos!$B$5,CEILING((K9*Supuestos!$B$3+Supuestos!$B$7)/1000,Supuestos!$B$6))*Supuestos!$B$4/Supuestos!$B$3,Supuestos!$B$8+D9*Supuestos!$B$9)) | M9: =IF(D9="","",(D9+E9+L9+(D9+E9)*Supuestos!$B$10)*Supuestos!$B$11) | N9: =IF(COUNT(G9:H9)=0,"",MIN(G9:H9)) | O9: =IF(OR(M9="",N9=""),"",N9-M9) | P9: =IF(O9="","",O9/N9) | Q9: =IF(P9="",IF(AND(D9="",N9=""),"Sin datos",IF(D9="","Sin precio eBay","Sin precio local")),IF(P9>=Supuestos!$B$12,"Conviene",IF(P9>=Supuestos!$B$13,"Justo","No conviene")))
A10: Ryzen 5 7600 | B10: CPU | C10: ver en eBay | D10: 199.99 | E10: 0 | F10: 114.99 | H10: 2800 | I10: =INDEX(Dólar!$B:$B,MATCH(MAX(Dólar!$A:$A),Dólar!$A:$A,0)) | J10: =INDEX(Dólar!$E:$E,MATCH(MAX(Dólar!$A:$A),Dólar!$A:$A,0)) | K10: 350 | L10: =IF(D10="","",MIN(MAX(Supuestos!$B$5,CEILING((K10*Supuestos!$B$3+Supuestos!$B$7)/1000,Supuestos!$B$6))*Supuestos!$B$4/Supuestos!$B$3,Supuestos!$B$8+D10*Supuestos!$B$9)) | M10: =IF(D10="","",(D10+E10+L10+(D10+E10)*Supuestos!$B$10)*Supuestos!$B$11) | N10: =IF(COUNT(G10:H10)=0,"",MIN(G10:H10)) | O10: =IF(OR(M10="",N10=""),"",N10-M10) | P10: =IF(O10="","",O10/N10) | Q10: =IF(P10="",IF(AND(D10="",N10=""),"Sin datos",IF(D10="","Sin precio eBay","Sin precio local")),IF(P10>=Supuestos!$B$12,"Conviene",IF(P10>=Supuestos!$B$13,"Justo","No conviene")))
A11: Ryzen 7 7700X | B11: CPU | C11: ver en eBay | D11: 199 | E11: 20 | F11: 189.99 | G11: 3000 | H11: 3480 | I11: =INDEX(Dólar!$B:$B,MATCH(MAX(Dólar!$A:$A),Dólar!$A:$A,0)) | J11: =INDEX(Dólar!$E:$E,MATCH(MAX(Dólar!$A:$A),Dólar!$A:$A,0)) | K11: 350 | L11: =IF(D11="","",MIN(MAX(Supuestos!$B$5,CEILING((K11*Supuestos!$B$3+Supuestos!$B$7)/1000,Supuestos!$B$6))*Supuestos!$B$4/Supuestos!$B$3,Supuestos!$B$8+D11*Supuestos!$B$9)) | M11: =IF(D11="","",(D11+E11+L11+(D11+E11)*Supuestos!$B$10)*Supuestos!$B$11) | N11: =IF(COUNT(G11:H11)=0,"",MIN(G11:H11)) | O11: =IF(OR(M11="",N11=""),"",N11-M11) | P11: =IF(O11="","",O11/N11) | Q11: =IF(P11="",IF(AND(D11="",N11=""),"Sin datos",IF(D11="","Sin precio eBay","Sin precio local")),IF(P11>=Supuestos!$B$12,"Conviene",IF(P11>=Supuestos!$B$13,"Justo","No conviene")))
A12: Corsair Vengeance RGB DDR5 32GB (2x16) 6000 | B12: RAM | C12: ver en eBay | D12: 450 | E12: 0 | F12: 419.99 | G12: 5800 | I12: =INDEX(Dólar!$B:$B,MATCH(MAX(Dólar!$A:$A),Dólar!$A:$A,0)) | J12: =INDEX(Dólar!$E:$E,MATCH(MAX(Dólar!$A:$A),Dólar!$A:$A,0)) | K12: 150 | L12: =IF(D12="","",MIN(MAX(Supuestos!$B$5,CEILING((K12*Supuestos!$B$3+Supuestos!$B$7)/1000,Supuestos!$B$6))*Supuestos!$B$4/Supuestos!$B$3,Supuestos!$B$8+D12*Supuestos!$B$9)) | M12: =IF(D12="","",(D12+E12+L12+(D12+E12)*Supuestos!$B$10)*Supuestos!$B$11) | N12: =IF(COUNT(G12:H12)=0,"",MIN(G12:H12)) | O12: =IF(OR(M12="",N12=""),"",N12-M12) | P12: =IF(O12="","",O12/N12) | Q12: =IF(P12="",IF(AND(D12="",N12=""),"Sin datos",IF(D12="","Sin precio eBay","Sin precio local")),IF(P12>=Supuestos!$B$12,"Conviene",IF(P12>=Supuestos!$B$13,"Justo","No conviene")))
A13: Ryzen 9 9950X | B13: CPU | C13: ver en eBay | D13: 549.99 | E13: 0 | F13: 454.99 | H13: 5580 | I13: =INDEX(Dólar!$B:$B,MATCH(MAX(Dólar!$A:$A),Dólar!$A:$A,0)) | J13: =INDEX(Dólar!$E:$E,MATCH(MAX(Dólar!$A:$A),Dólar!$A:$A,0)) | K13: 350 | L13: =IF(D13="","",MIN(MAX(Supuestos!$B$5,CEILING((K13*Supuestos!$B$3+Supuestos!$B$7)/1000,Supuestos!$B$6))*Supuestos!$B$4/Supuestos!$B$3,Supuestos!$B$8+D13*Supuestos!$B$9)) | M13: =IF(D13="","",(D13+E13+L13+(D13+E13)*Supuestos!$B$10)*Supuestos!$B$11) | N13: =IF(COUNT(G13:H13)=0,"",MIN(G13:H13)) | O13: =IF(OR(M13="",N13=""),"",N13-M13) | P13: =IF(O13="","",O13/N13) | Q13: =IF(P13="",IF(AND(D13="",N13=""),"Sin datos",IF(D13="","Sin precio eBay","Sin precio local")),IF(P13>=Supuestos!$B$12,"Conviene",IF(P13>=Supuestos!$B$13,"Justo","No conviene")))
A14: Corsair Vengeance RGB DDR5 32GB (2x16) 5600 | B14: RAM | C14: ver en eBay | D14: 459 | E14: 0 | F14: 389.99 | G14: 4500 | I14: =INDEX(Dólar!$B:$B,MATCH(MAX(Dólar!$A:$A),Dólar!$A:$A,0)) | J14: =INDEX(Dólar!$E:$E,MATCH(MAX(Dólar!$A:$A),Dólar!$A:$A,0)) | K14: 150 | L14: =IF(D14="","",MIN(MAX(Supuestos!$B$5,CEILING((K14*Supuestos!$B$3+Supuestos!$B$7)/1000,Supuestos!$B$6))*Supuestos!$B$4/Supuestos!$B$3,Supuestos!$B$8+D14*Supuestos!$B$9)) | M14: =IF(D14="","",(D14+E14+L14+(D14+E14)*Supuestos!$B$10)*Supuestos!$B$11) | N14: =IF(COUNT(G14:H14)=0,"",MIN(G14:H14)) | O14: =IF(OR(M14="",N14=""),"",N14-M14) | P14: =IF(O14="","",O14/N14) | Q14: =IF(P14="",IF(AND(D14="",N14=""),"Sin datos",IF(D14="","Sin precio eBay","Sin precio local")),IF(P14>=Supuestos!$B$12,"Conviene",IF(P14>=Supuestos!$B$13,"Justo","No conviene")))
A15: Intel Core i5-13400 | B15: CPU | C15: ver en eBay | D15: 259.78 | E15: 0 | F15: 129.99 | H15: 2300 | I15: =INDEX(Dólar!$B:$B,MATCH(MAX(Dólar!$A:$A),Dólar!$A:$A,0)) | J15: =INDEX(Dólar!$E:$E,MATCH(MAX(Dólar!$A:$A),Dólar!$A:$A,0)) | K15: 300 | L15: =IF(D15="","",MIN(MAX(Supuestos!$B$5,CEILING((K15*Supuestos!$B$3+Supuestos!$B$7)/1000,Supuestos!$B$6))*Supuestos!$B$4/Supuestos!$B$3,Supuestos!$B$8+D15*Supuestos!$B$9)) | M15: =IF(D15="","",(D15+E15+L15+(D15+E15)*Supuestos!$B$10)*Supuestos!$B$11) | N15: =IF(COUNT(G15:H15)=0,"",MIN(G15:H15)) | O15: =IF(OR(M15="",N15=""),"",N15-M15) | P15: =IF(O15="","",O15/N15) | Q15: =IF(P15="",IF(AND(D15="",N15=""),"Sin datos",IF(D15="","Sin precio eBay","Sin precio local")),IF(P15>=Supuestos!$B$12,"Conviene",IF(P15>=Supuestos!$B$13,"Justo","No conviene")))
A16: SSD NVMe 1TB | B16: SSD | C16: ver en eBay | D16: 119.99 | E16: 0 | F16: 99 | G16: 1100 | H16: 1754 | I16: =INDEX(Dólar!$B:$B,MATCH(MAX(Dólar!$A:$A),Dólar!$A:$A,0)) | J16: =INDEX(Dólar!$E:$E,MATCH(MAX(Dólar!$A:$A),Dólar!$A:$A,0)) | K16: 80 | L16: =IF(D16="","",MIN(MAX(Supuestos!$B$5,CEILING((K16*Supuestos!$B$3+Supuestos!$B$7)/1000,Supuestos!$B$6))*Supuestos!$B$4/Supuestos!$B$3,Supuestos!$B$8+D16*Supuestos!$B$9)) | M16: =IF(D16="","",(D16+E16+L16+(D16+E16)*Supuestos!$B$10)*Supuestos!$B$11) | N16: =IF(COUNT(G16:H16)=0,"",MIN(G16:H16)) | O16: =IF(OR(M16="",N16=""),"",N16-M16) | P16: =IF(O16="","",O16/N16) | Q16: =IF(P16="",IF(AND(D16="",N16=""),"Sin datos",IF(D16="","Sin precio eBay","Sin precio local")),IF(P16>=Supuestos!$B$12,"Conviene",IF(P16>=Supuestos!$B$13,"Justo","No conviene")))
A17: RAM DDR4 16GB (2x8) 3200 | B17: RAM | C17: ver en eBay | D17: 75 | E17: 0 | F17: 59.99 | G17: 540 | H17: 2150 | I17: =INDEX(Dólar!$B:$B,MATCH(MAX(Dólar!$A:$A),Dólar!$A:$A,0)) | J17: =INDEX(Dólar!$E:$E,MATCH(MAX(Dólar!$A:$A),Dólar!$A:$A,0)) | K17: 120 | L17: =IF(D17="","",MIN(MAX(Supuestos!$B$5,CEILING((K17*Supuestos!$B$3+Supuestos!$B$7)/1000,Supuestos!$B$6))*Supuestos!$B$4/Supuestos!$B$3,Supuestos!$B$8+D17*Supuestos!$B$9)) | M17: =IF(D17="","",(D17+E17+L17+(D17+E17)*Supuestos!$B$10)*Supuestos!$B$11) | N17: =IF(COUNT(G17:H17)=0,"",MIN(G17:H17)) | O17: =IF(OR(M17="",N17=""),"",N17-M17) | P17: =IF(O17="","",O17/N17) | Q17: =IF(P17="",IF(AND(D17="",N17=""),"Sin datos",IF(D17="","Sin precio eBay","Sin precio local")),IF(P17>=Supuestos!$B$12,"Conviene",IF(P17>=Supuestos!$B$13,"Justo","No conviene")))
A18: Ryzen 5 5600 | B18: CPU | C18: ver en eBay | D18: 138.9 | E18: 0 | F18: 131.99 | I18: =INDEX(Dólar!$B:$B,MATCH(MAX(Dólar!$A:$A),Dólar!$A:$A,0)) | J18: =INDEX(Dólar!$E:$E,MATCH(MAX(Dólar!$A:$A),Dólar!$A:$A,0)) | K18: 350 | L18: =IF(D18="","",MIN(MAX(Supuestos!$B$5,CEILING((K18*Supuestos!$B$3+Supuestos!$B$7)/1000,Supuestos!$B$6))*Supuestos!$B$4/Supuestos!$B$3,Supuestos!$B$8+D18*Supuestos!$B$9)) | M18: =IF(D18="","",(D18+E18+L18+(D18+E18)*Supuestos!$B$10)*Supuestos!$B$11) | N18: =IF(COUNT(G18:H18)=0,"",MIN(G18:H18)) | O18: =IF(OR(M18="",N18=""),"",N18-M18) | P18: =IF(O18="","",O18/N18) | Q18: =IF(P18="",IF(AND(D18="",N18=""),"Sin datos",IF(D18="","Sin precio eBay","Sin precio local")),IF(P18>=Supuestos!$B$12,"Conviene",IF(P18>=Supuestos!$B$13,"Justo","No conviene")))
A19: Ryzen 7 5700X3D | B19: CPU | C19: ver en eBay | F19: 336 | I19: =INDEX(Dólar!$B:$B,MATCH(MAX(Dólar!$A:$A),Dólar!$A:$A,0)) | J19: =INDEX(Dólar!$E:$E,MATCH(MAX(Dólar!$A:$A),Dólar!$A:$A,0)) | K19: 350 | L19: =IF(D19="","",MIN(MAX(Supuestos!$B$5,CEILING((K19*Supuestos!$B$3+Supuestos!$B$7)/1000,Supuestos!$B$6))*Supuestos!$B$4/Supuestos!$B$3,Supuestos!$B$8+D19*Supuestos!$B$9)) | M19: =IF(D19="","",(D19+E19+L19+(D19+E19)*Supuestos!$B$10)*Supuestos!$B$11) | N19: =IF(COUNT(G19:H19)=0,"",MIN(G19:H19)) | O19: =IF(OR(M19="",N19=""),"",N19-M19) | P19: =IF(O19="","",O19/N19) | Q19: =IF(P19="",IF(AND(D19="",N19=""),"Sin datos",IF(D19="","Sin precio eBay","Sin precio local")),IF(P19>=Supuestos!$B$12,"Conviene",IF(P19>=Supuestos!$B$13,"Justo","No conviene")))
A20: Ryzen 5 7500F | B20: CPU | C20: ver en eBay | D20: 135.6 | E20: 0 | F20: 114.99 | I20: =INDEX(Dólar!$B:$B,MATCH(MAX(Dólar!$A:$A),Dólar!$A:$A,0)) | J20: =INDEX(Dólar!$E:$E,MATCH(MAX(Dólar!$A:$A),Dólar!$A:$A,0)) | K20: 350 | L20: =IF(D20="","",MIN(MAX(Supuestos!$B$5,CEILING((K20*Supuestos!$B$3+Supuestos!$B$7)/1000,Supuestos!$B$6))*Supuestos!$B$4/Supuestos!$B$3,Supuestos!$B$8+D20*Supuestos!$B$9)) | M20: =IF(D20="","",(D20+E20+L20+(D20+E20)*Supuestos!$B$10)*Supuestos!$B$11) | N20: =IF(COUNT(G20:H20)=0,"",MIN(G20:H20)) | O20: =IF(OR(M20="",N20=""),"",N20-M20) | P20: =IF(O20="","",O20/N20) | Q20: =IF(P20="",IF(AND(D20="",N20=""),"Sin datos",IF(D20="","Sin precio eBay","Sin precio local")),IF(P20>=Supuestos!$B$12,"Conviene",IF(P20>=Supuestos!$B$13,"Justo","No conviene")))
A22: Azul: datos de eBay, Marketplace y tiendas (de los CSV del repo). Negro: fórmulas. Para probar otros supuestos (unidades, aduana, dólar) cambia la hoja Supuestos.

Sheet Historial
A1: Fecha | B1: Producto | C1: Tipo | D1: eBay nuevo USD | E1: eBay usado USD | F1: Marketplace Bs | G1: Tiendas Bs | H1: Dólar BCB | I1: Dólar paralelo | J1: Link del producto | K1: Fecha anterior | L1: Δ eBay nuevo | M1: Δ eBay usado | N1: Δ Marketplace | O1: Δ Tiendas
A2: 46325 | B2: SSD NVMe 2TB | C2: SSD | D2: 185 | F2: 3100 | H2: =IFERROR(IF(INDEX(Dólar!$B:$B,MATCH(A2,Dólar!$A:$A,0))="","",INDEX(Dólar!$B:$B,MATCH(A2,Dólar!$A:$A,0))),"") | I2: =IFERROR(INDEX(Dólar!$E:$E,MATCH(A2,Dólar!$A:$A,0)),"") | J2: ver anuncio | K2: 46324 | L2: =IF(OR($K2="",D2=""),"",IF(COUNTIFS($B:$B,$B2,$A:$A,$K2,D:D,">=0")=0,"",D2-SUMIFS(D:D,$B:$B,$B2,$A:$A,$K2))) | M2: =IF(OR($K2="",E2=""),"",IF(COUNTIFS($B:$B,$B2,$A:$A,$K2,E:E,">=0")=0,"",E2-SUMIFS(E:E,$B:$B,$B2,$A:$A,$K2))) | N2: =IF(OR($K2="",F2=""),"",IF(COUNTIFS($B:$B,$B2,$A:$A,$K2,F:F,">=0")=0,"",F2-SUMIFS(F:F,$B:$B,$B2,$A:$A,$K2))) | O2: =IF(OR($K2="",G2=""),"",IF(COUNTIFS($B:$B,$B2,$A:$A,$K2,G:G,">=0")=0,"",G2-SUMIFS(G:G,$B:$B,$B2,$A:$A,$K2)))
A3: 46325 | B3: SSD NVMe 1TB | C3: SSD | D3: 119.99 | F3: 1675 | H3: =IFERROR(IF(INDEX(Dólar!$B:$B,MATCH(A3,Dólar!$A:$A,0))="","",INDEX(Dólar!$B:$B,MATCH(A3,Dólar!$A:$A,0))),"") | I3: =IFERROR(INDEX(Dólar!$E:$E,MATCH(A3,Dólar!$A:$A,0)),"") | J3: ver anuncio | K3: 46324 | L3: =IF(OR($K3="",D3=""),"",IF(COUNTIFS($B:$B,$B3,$A:$A,$K3,D:D,">=0")=0,"",D3-SUMIFS(D:D,$B:$B,$B3,$A:$A,$K3))) | M3: =IF(OR($K3="",E3=""),"",IF(COUNTIFS($B:$B,$B3,$A:$A,$K3,E:E,">=0")=0,"",E3-SUMIFS(E:E,$B:$B,$B3,$A:$A,$K3))) | N3: =IF(OR($K3="",F3=""),"",IF(COUNTIFS($B:$B,$B3,$A:$A,$K3,F:F,">=0")=0,"",F3-SUMIFS(F:F,$B:$B,$B3,$A:$A,$K3))) | O3: =IF(OR($K3="",G3=""),"",IF(COUNTIFS($B:$B,$B3,$A:$A,$K3,G:G,">=0")=0,"",G3-SUMIFS(G:G,$B:$B,$B3,$A:$A,$K3)))
A4: 46325 | B4: Ryzen 9 9950X | C4: CPU | D4: 549.99 | H4: =IFERROR(IF(INDEX(Dólar!$B:$B,MATCH(A4,Dólar!$A:$A,0))="","",INDEX(Dólar!$B:$B,MATCH(A4,Dólar!$A:$A,0))),"") | I4: =IFERROR(INDEX(Dólar!$E:$E,MATCH(A4,Dólar!$A:$A,0)),"") | J4: ver anuncio | K4: 46324 | L4: =IF(OR($K4="",D4=""),"",IF(COUNTIFS($B:$B,$B4,$A:$A,$K4,D:D,">=0")=0,"",D4-SUMIFS(D:D,$B:$B,$B4,$A:$A,$K4))) | M4: =IF(OR($K4="",E4=""),"",IF(COUNTIFS($B:$B,$B4,$A:$A,$K4,E:E,">=0")=0,"",E4-SUMIFS(E:E,$B:$B,$B4,$A:$A,$K4))) | N4: =IF(OR($K4="",F4=""),"",IF(COUNTIFS($B:$B,$B4,$A:$A,$K4,F:F,">=0")=0,"",F4-SUMIFS(F:F,$B:$B,$B4,$A:$A,$K4))) | O4: =IF(OR($K4="",G4=""),"",IF(COUNTIFS($B:$B,$B4,$A:$A,$K4,G:G,">=0")=0,"",G4-SUMIFS(G:G,$B:$B,$B4,$A:$A,$K4)))
A5: 46325 | B5: Ryzen 7 7800X3D | C5: CPU | D5: 329 | F5: 5190 | H5: =IFERROR(IF(INDEX(Dólar!$B:$B,MATCH(A5,Dólar!$A:$A,0))="","",INDEX(Dólar!$B:$B,MATCH(A5,Dólar!$A:$A,0))),"") | I5: =IFERROR(INDEX(Dólar!$E:$E,MATCH(A5,Dólar!$A:$A,0)),"") | J5: ver anuncio | K5: 46324 | L5: =IF(OR($K5="",D5=""),"",IF(COUNTIFS($B:$B,$B5,$A:$A,$K5,D:D,">=0")=0,"",D5-SUMIFS(D:D,$B:$B,$B5,$A:$A,$K5))) | M5: =IF(OR($K5="",E5=""),"",IF(COUNTIFS($B:$B,$B5,$A:$A,$K5,E:E,">=0")=0,"",E5-SUMIFS(E:E,$B:$B,$B5,$A:$A,$K5))) | N5: =IF(OR($K5="",F5=""),"",IF(COUNTIFS($B:$B,$B5,$A:$A,$K5,F:F,">=0")=0,"",F5-SUMIFS(F:F,$B:$B,$B5,$A:$A,$K5))) | O5: =IF(OR($K5="",G5=""),"",IF(COUNTIFS($B:$B,$B5,$A:$A,$K5,G:G,">=0")=0,"",G5-SUMIFS(G:G,$B:$B,$B5,$A:$A,$K5)))
A6: 46325 | B6: Ryzen 7 7700X | C6: CPU | D6: 219 | F6: 3000 | H6: =IFERROR(IF(INDEX(Dólar!$B:$B,MATCH(A6,Dólar!$A:$A,0))="","",INDEX(Dólar!$B:$B,MATCH(A6,Dólar!$A:$A,0))),"") | I6: =IFERROR(INDEX(Dólar!$E:$E,MATCH(A6,Dólar!$A:$A,0)),"") | J6: ver anuncio | K6: 46324 | L6: =IF(OR($K6="",D6=""),"",IF(COUNTIFS($B:$B,$B6,$A:$A,$K6,D:D,">=0")=0,"",D6-SUMIFS(D:D,$B:$B,$B6,$A:$A,$K6))) | M6: =IF(OR($K6="",E6=""),"",IF(COUNTIFS($B:$B,$B6,$A:$A,$K6,E:E,">=0")=0,"",E6-SUMIFS(E:E,$B:$B,$B6,$A:$A,$K6))) | N6: =IF(OR($K6="",F6=""),"",IF(COUNTIFS($B:$B,$B6,$A:$A,$K6,F:F,">=0")=0,"",F6-SUMIFS(F:F,$B:$B,$B6,$A:$A,$K6))) | O6: =IF(OR($K6="",G6=""),"",IF(COUNTIFS($B:$B,$B6,$A:$A,$K6,G:G,">=0")=0,"",G6-SUMIFS(G:G,$B:$B,$B6,$A:$A,$K6)))
A7: 46325 | B7: Ryzen 5 7600 | C7: CPU | D7: 199.99 | H7: =IFERROR(IF(INDEX(Dólar!$B:$B,MATCH(A7,Dólar!$A:$A,0))="","",INDEX(Dólar!$B:$B,MATCH(A7,Dólar!$A:$A,0))),"") | I7: =IFERROR(INDEX(Dólar!$E:$E,MATCH(A7,Dólar!$A:$A,0)),"") | J7: ver anuncio | K7: 46324 | L7: =IF(OR($K7="",D7=""),"",IF(COUNTIFS($B:$B,$B7,$A:$A,$K7,D:D,">=0")=0,"",D7-SUMIFS(D:D,$B:$B,$B7,$A:$A,$K7))) | M7: =IF(OR($K7="",E7=""),"",IF(COUNTIFS($B:$B,$B7,$A:$A,$K7,E:E,">=0")=0,"",E7-SUMIFS(E:E,$B:$B,$B7,$A:$A,$K7))) | N7: =IF(OR($K7="",F7=""),"",IF(COUNTIFS($B:$B,$B7,$A:$A,$K7,F:F,">=0")=0,"",F7-SUMIFS(F:F,$B:$B,$B7,$A:$A,$K7))) | O7: =IF(OR($K7="",G7=""),"",IF(COUNTIFS($B:$B,$B7,$A:$A,$K7,G:G,">=0")=0,"",G7-SUMIFS(G:G,$B:$B,$B7,$A:$A,$K7)))
A8: 46325 | B8: Ryzen 5 7500F | C8: CPU | D8: 135.6 | H8: =IFERROR(IF(INDEX(Dólar!$B:$B,MATCH(A8,Dólar!$A:$A,0))="","",INDEX(Dólar!$B:$B,MATCH(A8,Dólar!$A:$A,0))),"") | I8: =IFERROR(INDEX(Dólar!$E:$E,MATCH(A8,Dólar!$A:$A,0)),"") | J8: ver anuncio | K8: 46324 | L8: =IF(OR($K8="",D8=""),"",IF(COUNTIFS($B:$B,$B8,$A:$A,$K8,D:D,">=0")=0,"",D8-SUMIFS(D:D,$B:$B,$B8,$A:$A,$K8))) | M8: =IF(OR($K8="",E8=""),"",IF(COUNTIFS($B:$B,$B8,$A:$A,$K8,E:E,">=0")=0,"",E8-SUMIFS(E:E,$B:$B,$B8,$A:$A,$K8))) | N8: =IF(OR($K8="",F8=""),"",IF(COUNTIFS($B:$B,$B8,$A:$A,$K8,F:F,">=0")=0,"",F8-SUMIFS(F:F,$B:$B,$B8,$A:$A,$K8))) | O8: =IF(OR($K8="",G8=""),"",IF(COUNTIFS($B:$B,$B8,$A:$A,$K8,G:G,">=0")=0,"",G8-SUMIFS(G:G,$B:$B,$B8,$A:$A,$K8)))
A9: 46325 | B9: Ryzen 5 5600 | C9: CPU | D9: 138.9 | H9: =IFERROR(IF(INDEX(Dólar!$B:$B,MATCH(A9,Dólar!$A:$A,0))="","",INDEX(Dólar!$B:$B,MATCH(A9,Dólar!$A:$A,0))),"") | I9: =IFERROR(INDEX(Dólar!$E:$E,MATCH(A9,Dólar!$A:$A,0)),"") | J9: ver anuncio | K9: 46324 | L9: =IF(OR($K9="",D9=""),"",IF(COUNTIFS($B:$B,$B9,$A:$A,$K9,D:D,">=0")=0,"",D9-SUMIFS(D:D,$B:$B,$B9,$A:$A,$K9))) | M9: =IF(OR($K9="",E9=""),"",IF(COUNTIFS($B:$B,$B9,$A:$A,$K9,E:E,">=0")=0,"",E9-SUMIFS(E:E,$B:$B,$B9,$A:$A,$K9))) | N9: =IF(OR($K9="",F9=""),"",IF(COUNTIFS($B:$B,$B9,$A:$A,$K9,F:F,">=0")=0,"",F9-SUMIFS(F:F,$B:$B,$B9,$A:$A,$K9))) | O9: =IF(OR($K9="",G9=""),"",IF(COUNTIFS($B:$B,$B9,$A:$A,$K9,G:G,">=0")=0,"",G9-SUMIFS(G:G,$B:$B,$B9,$A:$A,$K9)))
A10: 46325 | B10: RAM DDR4 16GB (2x8) 3200 | C10: RAM | D10: 75 | H10: =IFERROR(IF(INDEX(Dólar!$B:$B,MATCH(A10,Dólar!$A:$A,0))="","",INDEX(Dólar!$B:$B,MATCH(A10,Dólar!$A:$A,0))),"") | I10: =IFERROR(INDEX(Dólar!$E:$E,MATCH(A10,Dólar!$A:$A,0)),"") | J10: ver anuncio | K10: 46324 | L10: =IF(OR($K10="",D10=""),"",IF(COUNTIFS($B:$B,$B10,$A:$A,$K10,D:D,">=0")=0,"",D10-SUMIFS(D:D,$B:$B,$B10,$A:$A,$K10))) | M10: =IF(OR($K10="",E10=""),"",IF(COUNTIFS($B:$B,$B10,$A:$A,$K10,E:E,">=0")=0,"",E10-SUMIFS(E:E,$B:$B,$B10,$A:$A,$K10))) | N10: =IF(OR($K10="",F10=""),"",IF(COUNTIFS($B:$B,$B10,$A:$A,$K10,F:F,">=0")=0,"",F10-SUMIFS(F:F,$B:$B,$B10,$A:$A,$K10))) | O10: =IF(OR($K10="",G10=""),"",IF(COUNTIFS($B:$B,$B10,$A:$A,$K10,G:G,">=0")=0,"",G10-SUMIFS(G:G,$B:$B,$B10,$A:$A,$K10)))
A11: 46325 | B11: Intel Core i5-14400F | C11: CPU | D11: 164.49 | H11: =IFERROR(IF(INDEX(Dólar!$B:$B,MATCH(A11,Dólar!$A:$A,0))="","",INDEX(Dólar!$B:$B,MATCH(A11,Dólar!$A:$A,0))),"") | I11: =IFERROR(INDEX(Dólar!$E:$E,MATCH(A11,Dólar!$A:$A,0)),"") | J11: ver anuncio | K11: 46324 | L11: =IF(OR($K11="",D11=""),"",IF(COUNTIFS($B:$B,$B11,$A:$A,$K11,D:D,">=0")=0,"",D11-SUMIFS(D:D,$B:$B,$B11,$A:$A,$K11))) | M11: =IF(OR($K11="",E11=""),"",IF(COUNTIFS($B:$B,$B11,$A:$A,$K11,E:E,">=0")=0,"",E11-SUMIFS(E:E,$B:$B,$B11,$A:$A,$K11))) | N11: =IF(OR($K11="",F11=""),"",IF(COUNTIFS($B:$B,$B11,$A:$A,$K11,F:F,">=0")=0,"",F11-SUMIFS(F:F,$B:$B,$B11,$A:$A,$K11))) | O11: =IF(OR($K11="",G11=""),"",IF(COUNTIFS($B:$B,$B11,$A:$A,$K11,G:G,">=0")=0,"",G11-SUMIFS(G:G,$B:$B,$B11,$A:$A,$K11)))
A12: 46325 | B12: Intel Core i5-13400 | C12: CPU | H12: =IFERROR(IF(INDEX(Dólar!$B:$B,MATCH(A12,Dólar!$A:$A,0))="","",INDEX(Dólar!$B:$B,MATCH(A12,Dólar!$A:$A,0))),"") | I12: =IFERROR(INDEX(Dólar!$E:$E,MATCH(A12,Dólar!$A:$A,0)),"") | K12: 46324 | L12: =IF(OR($K12="",D12=""),"",IF(COUNTIFS($B:$B,$B12,$A:$A,$K12,D:D,">=0")=0,"",D12-SUMIFS(D:D,$B:$B,$B12,$A:$A,$K12))) | M12: =IF(OR($K12="",E12=""),"",IF(COUNTIFS($B:$B,$B12,$A:$A,$K12,E:E,">=0")=0,"",E12-SUMIFS(E:E,$B:$B,$B12,$A:$A,$K12))) | N12: =IF(OR($K12="",F12=""),"",IF(COUNTIFS($B:$B,$B12,$A:$A,$K12,F:F,">=0")=0,"",F12-SUMIFS(F:F,$B:$B,$B12,$A:$A,$K12))) | O12: =IF(OR($K12="",G12=""),"",IF(COUNTIFS($B:$B,$B12,$A:$A,$K12,G:G,">=0")=0,"",G12-SUMIFS(G:G,$B:$B,$B12,$A:$A,$K12)))
A13: 46325 | B13: Intel Core i5-12400F | C13: CPU | D13: 140 | H13: =IFERROR(IF(INDEX(Dólar!$B:$B,MATCH(A13,Dólar!$A:$A,0))="","",INDEX(Dólar!$B:$B,MATCH(A13,Dólar!$A:$A,0))),"") | I13: =IFERROR(INDEX(Dólar!$E:$E,MATCH(A13,Dólar!$A:$A,0)),"") | J13: ver anuncio | K13: 46324 | L13: =IF(OR($K13="",D13=""),"",IF(COUNTIFS($B:$B,$B13,$A:$A,$K13,D:D,">=0")=0,"",D13-SUMIFS(D:D,$B:$B,$B13,$A:$A,$K13))) | M13: =IF(OR($K13="",E13=""),"",IF(COUNTIFS($B:$B,$B13,$A:$A,$K13,E:E,">=0")=0,"",E13-SUMIFS(E:E,$B:$B,$B13,$A:$A,$K13))) | N13: =IF(OR($K13="",F13=""),"",IF(COUNTIFS($B:$B,$B13,$A:$A,$K13,F:F,">=0")=0,"",F13-SUMIFS(F:F,$B:$B,$B13,$A:$A,$K13))) | O13: =IF(OR($K13="",G13=""),"",IF(COUNTIFS($B:$B,$B13,$A:$A,$K13,G:G,">=0")=0,"",G13-SUMIFS(G:G,$B:$B,$B13,$A:$A,$K13)))
A14: 46325 | B14: Intel Core Ultra 7 265K | C14: CPU | D14: 248 | H14: =IFERROR(IF(INDEX(Dólar!$B:$B,MATCH(A14,Dólar!$A:$A,0))="","",INDEX(Dólar!$B:$B,MATCH(A14,Dólar!$A:$A,0))),"") | I14: =IFERROR(INDEX(Dólar!$E:$E,MATCH(A14,Dólar!$A:$A,0)),"") | J14: ver anuncio | K14: 46324 | L14: =IF(OR($K14="",D14=""),"",IF(COUNTIFS($B:$B,$B14,$A:$A,$K14,D:D,">=0")=0,"",D14-SUMIFS(D:D,$B:$B,$B14,$A:$A,$K14))) | M14: =IF(OR($K14="",E14=""),"",IF(COUNTIFS($B:$B,$B14,$A:$A,$K14,E:E,">=0")=0,"",E14-SUMIFS(E:E,$B:$B,$B14,$A:$A,$K14))) | N14: =IF(OR($K14="",F14=""),"",IF(COUNTIFS($B:$B,$B14,$A:$A,$K14,F:F,">=0")=0,"",F14-SUMIFS(F:F,$B:$B,$B14,$A:$A,$K14))) | O14: =IF(OR($K14="",G14=""),"",IF(COUNTIFS($B:$B,$B14,$A:$A,$K14,G:G,">=0")=0,"",G14-SUMIFS(G:G,$B:$B,$B14,$A:$A,$K14)))
A15: 46325 | B15: Corsair Vengeance RGB DDR5 32GB (2x16) 6000 | C15: RAM | D15: 450 | F15: 6200 | H15: =IFERROR(IF(INDEX(Dólar!$B:$B,MATCH(A15,Dólar!$A:$A,0))="","",INDEX(Dólar!$B:$B,MATCH(A15,Dólar!$A:$A,0))),"") | I15: =IFERROR(INDEX(Dólar!$E:$E,MATCH(A15,Dólar!$A:$A,0)),"") | J15: ver anuncio | K15: 46324 | L15: =IF(OR($K15="",D15=""),"",IF(COUNTIFS($B:$B,$B15,$A:$A,$K15,D:D,">=0")=0,"",D15-SUMIFS(D:D,$B:$B,$B15,$A:$A,$K15))) | M15: =IF(OR($K15="",E15=""),"",IF(COUNTIFS($B:$B,$B15,$A:$A,$K15,E:E,">=0")=0,"",E15-SUMIFS(E:E,$B:$B,$B15,$A:$A,$K15))) | N15: =IF(OR($K15="",F15=""),"",IF(COUNTIFS($B:$B,$B15,$A:$A,$K15,F:F,">=0")=0,"",F15-SUMIFS(F:F,$B:$B,$B15,$A:$A,$K15))) | O15: =IF(OR($K15="",G15=""),"",IF(COUNTIFS($B:$B,$B15,$A:$A,$K15,G:G,">=0")=0,"",G15-SUMIFS(G:G,$B:$B,$B15,$A:$A,$K15)))
A16: 46325 | B16: Corsair Vengeance RGB DDR5 32GB (2x16) 5600 | C16: RAM | D16: 459 | H16: =IFERROR(IF(INDEX(Dólar!$B:$B,MATCH(A16,Dólar!$A:$A,0))="","",INDEX(Dólar!$B:$B,MATCH(A16,Dólar!$A:$A,0))),"") | I16: =IFERROR(INDEX(Dólar!$E:$E,MATCH(A16,Dólar!$A:$A,0)),"") | J16: ver anuncio | K16: 46324 | L16: =IF(OR($K16="",D16=""),"",IF(COUNTIFS($B:$B,$B16,$A:$A,$K16,D:D,">=0")=0,"",D16-SUMIFS(D:D,$B:$B,$B16,$A:$A,$K16))) | M16: =IF(OR($K16="",E16=""),"",IF(COUNTIFS($B:$B,$B16,$A:$A,$K16,E:E,">=0")=0,"",E16-SUMIFS(E:E,$B:$B,$B16,$A:$A,$K16))) | N16: =IF(OR($K16="",F16=""),"",IF(COUNTIFS($B:$B,$B16,$A:$A,$K16,F:F,">=0")=0,"",F16-SUMIFS(F:F,$B:$B,$B16,$A:$A,$K16))) | O16: =IF(OR($K16="",G16=""),"",IF(COUNTIFS($B:$B,$B16,$A:$A,$K16,G:G,">=0")=0,"",G16-SUMIFS(G:G,$B:$B,$B16,$A:$A,$K16)))
A17: 46324 | B17: SSD NVMe 2TB | C17: SSD | D17: 209.99 | E17: 154.99 | H17: =IFERROR(IF(INDEX(Dólar!$B:$B,MATCH(A17,Dólar!$A:$A,0))="","",INDEX(Dólar!$B:$B,MATCH(A17,Dólar!$A:$A,0))),"") | I17: =IFERROR(INDEX(Dólar!$E:$E,MATCH(A17,Dólar!$A:$A,0)),"") | J17: ver anuncio | K17: 46323 | L17: =IF(OR($K17="",D17=""),"",IF(COUNTIFS($B:$B,$B17,$A:$A,$K17,D:D,">=0")=0,"",D17-SUMIFS(D:D,$B:$B,$B17,$A:$A,$K17))) | M17: =IF(OR($K17="",E17=""),"",IF(COUNTIFS($B:$B,$B17,$A:$A,$K17,E:E,">=0")=0,"",E17-SUMIFS(E:E,$B:$B,$B17,$A:$A,$K17))) | N17: =IF(OR($K17="",F17=""),"",IF(COUNTIFS($B:$B,$B17,$A:$A,$K17,F:F,">=0")=0,"",F17-SUMIFS(F:F,$B:$B,$B17,$A:$A,$K17))) | O17: =IF(OR($K17="",G17=""),"",IF(COUNTIFS($B:$B,$B17,$A:$A,$K17,G:G,">=0")=0,"",G17-SUMIFS(G:G,$B:$B,$B17,$A:$A,$K17)))
A18: 46324 | B18: SSD NVMe 1TB | C18: SSD | D18: 135 | E18: 99 | H18: =IFERROR(IF(INDEX(Dólar!$B:$B,MATCH(A18,Dólar!$A:$A,0))="","",INDEX(Dólar!$B:$B,MATCH(A18,Dólar!$A:$A,0))),"") | I18: =IFERROR(INDEX(Dólar!$E:$E,MATCH(A18,Dólar!$A:$A,0)),"") | J18: ver anuncio | K18: 46323 | L18: =IF(OR($K18="",D18=""),"",IF(COUNTIFS($B:$B,$B18,$A:$A,$K18,D:D,">=0")=0,"",D18-SUMIFS(D:D,$B:$B,$B18,$A:$A,$K18))) | M18: =IF(OR($K18="",E18=""),"",IF(COUNTIFS($B:$B,$B18,$A:$A,$K18,E:E,">=0")=0,"",E18-SUMIFS(E:E,$B:$B,$B18,$A:$A,$K18))) | N18: =IF(OR($K18="",F18=""),"",IF(COUNTIFS($B:$B,$B18,$A:$A,$K18,F:F,">=0")=0,"",F18-SUMIFS(F:F,$B:$B,$B18,$A:$A,$K18))) | O18: =IF(OR($K18="",G18=""),"",IF(COUNTIFS($B:$B,$B18,$A:$A,$K18,G:G,">=0")=0,"",G18-SUMIFS(G:G,$B:$B,$B18,$A:$A,$K18)))
A19: 46324 | B19: Ryzen 9 9950X | C19: CPU | D19: 549.99 | E19: 454.99 | H19: =IFERROR(IF(INDEX(Dólar!$B:$B,MATCH(A19,Dólar!$A:$A,0))="","",INDEX(Dólar!$B:$B,MATCH(A19,Dólar!$A:$A,0))),"") | I19: =IFERROR(INDEX(Dólar!$E:$E,MATCH(A19,Dólar!$A:$A,0)),"") | J19: ver anuncio | K19: 46323 | L19: =IF(OR($K19="",D19=""),"",IF(COUNTIFS($B:$B,$B19,$A:$A,$K19,D:D,">=0")=0,"",D19-SUMIFS(D:D,$B:$B,$B19,$A:$A,$K19))) | M19: =IF(OR($K19="",E19=""),"",IF(COUNTIFS($B:$B,$B19,$A:$A,$K19,E:E,">=0")=0,"",E19-SUMIFS(E:E,$B:$B,$B19,$A:$A,$K19))) | N19: =IF(OR($K19="",F19=""),"",IF(COUNTIFS($B:$B,$B19,$A:$A,$K19,F:F,">=0")=0,"",F19-SUMIFS(F:F,$B:$B,$B19,$A:$A,$K19))) | O19: =IF(OR($K19="",G19=""),"",IF(COUNTIFS($B:$B,$B19,$A:$A,$K19,G:G,">=0")=0,"",G19-SUMIFS(G:G,$B:$B,$B19,$A:$A,$K19)))
A20: 46324 | B20: Ryzen 7 7800X3D | C20: CPU | D20: 325 | E20: 265 | H20: =IFERROR(IF(INDEX(Dólar!$B:$B,MATCH(A20,Dólar!$A:$A,0))="","",INDEX(Dólar!$B:$B,MATCH(A20,Dólar!$A:$A,0))),"") | I20: =IFERROR(INDEX(Dólar!$E:$E,MATCH(A20,Dólar!$A:$A,0)),"") | J20: ver anuncio | K20: 46323 | L20: =IF(OR($K20="",D20=""),"",IF(COUNTIFS($B:$B,$B20,$A:$A,$K20,D:D,">=0")=0,"",D20-SUMIFS(D:D,$B:$B,$B20,$A:$A,$K20))) | M20: =IF(OR($K20="",E20=""),"",IF(COUNTIFS($B:$B,$B20,$A:$A,$K20,E:E,">=0")=0,"",E20-SUMIFS(E:E,$B:$B,$B20,$A:$A,$K20))) | N20: =IF(OR($K20="",F20=""),"",IF(COUNTIFS($B:$B,$B20,$A:$A,$K20,F:F,">=0")=0,"",F20-SUMIFS(F:F,$B:$B,$B20,$A:$A,$K20))) | O20: =IF(OR($K20="",G20=""),"",IF(COUNTIFS($B:$B,$B20,$A:$A,$K20,G:G,">=0")=0,"",G20-SUMIFS(G:G,$B:$B,$B20,$A:$A,$K20)))
A21: 46324 | B21: Ryzen 7 7700X | C21: CPU | D21: 219 | E21: 189.99 | H21: =IFERROR(IF(INDEX(Dólar!$B:$B,MATCH(A21,Dólar!$A:$A,0))="","",INDEX(Dólar!$B:$B,MATCH(A21,Dólar!$A:$A,0))),"") | I21: =IFERROR(INDEX(Dólar!$E:$E,MATCH(A21,Dólar!$A:$A,0)),"") | J21: ver anuncio | K21: 46323 | L21: =IF(OR($K21="",D21=""),"",IF(COUNTIFS($B:$B,$B21,$A:$A,$K21,D:D,">=0")=0,"",D21-SUMIFS(D:D,$B:$B,$B21,$A:$A,$K21))) | M21: =IF(OR($K21="",E21=""),"",IF(COUNTIFS($B:$B,$B21,$A:$A,$K21,E:E,">=0")=0,"",E21-SUMIFS(E:E,$B:$B,$B21,$A:$A,$K21))) | N21: =IF(OR($K21="",F21=""),"",IF(COUNTIFS($B:$B,$B21,$A:$A,$K21,F:F,">=0")=0,"",F21-SUMIFS(F:F,$B:$B,$B21,$A:$A,$K21))) | O21: =IF(OR($K21="",G21=""),"",IF(COUNTIFS($B:$B,$B21,$A:$A,$K21,G:G,">=0")=0,"",G21-SUMIFS(G:G,$B:$B,$B21,$A:$A,$K21)))
A22: 46324 | B22: Ryzen 7 5700X3D | C22: CPU | E22: 336 | H22: =IFERROR(IF(INDEX(Dólar!$B:$B,MATCH(A22,Dólar!$A:$A,0))="","",INDEX(Dólar!$B:$B,MATCH(A22,Dólar!$A:$A,0))),"") | I22: =IFERROR(INDEX(Dólar!$E:$E,MATCH(A22,Dólar!$A:$A,0)),"") | J22: ver anuncio | K22: 46323 | L22: =IF(OR($K22="",D22=""),"",IF(COUNTIFS($B:$B,$B22,$A:$A,$K22,D:D,">=0")=0,"",D22-SUMIFS(D:D,$B:$B,$B22,$A:$A,$K22))) | M22: =IF(OR($K22="",E22=""),"",IF(COUNTIFS($B:$B,$B22,$A:$A,$K22,E:E,">=0")=0,"",E22-SUMIFS(E:E,$B:$B,$B22,$A:$A,$K22))) | N22: =IF(OR($K22="",F22=""),"",IF(COUNTIFS($B:$B,$B22,$A:$A,$K22,F:F,">=0")=0,"",F22-SUMIFS(F:F,$B:$B,$B22,$A:$A,$K22))) | O22: =IF(OR($K22="",G22=""),"",IF(COUNTIFS($B:$B,$B22,$A:$A,$K22,G:G,">=0")=0,"",G22-SUMIFS(G:G,$B:$B,$B22,$A:$A,$K22)))
A23: 46324 | B23: Ryzen 5 7600 | C23: CPU | D23: 199.99 | E23: 114.99 | H23: =IFERROR(IF(INDEX(Dólar!$B:$B,MATCH(A23,Dólar!$A:$A,0))="","",INDEX(Dólar!$B:$B,MATCH(A23,Dólar!$A:$A,0))),"") | I23: =IFERROR(INDEX(Dólar!$E:$E,MATCH(A23,Dólar!$A:$A,0)),"") | J23: ver anuncio | K23: 46323 | L23: =IF(OR($K23="",D23=""),"",IF(COUNTIFS($B:$B,$B23,$A:$A,$K23,D:D,">=0")=0,"",D23-SUMIFS(D:D,$B:$B,$B23,$A:$A,$K23))) | M23: =IF(OR($K23="",E23=""),"",IF(COUNTIFS($B:$B,$B23,$A:$A,$K23,E:E,">=0")=0,"",E23-SUMIFS(E:E,$B:$B,$B23,$A:$A,$K23))) | N23: =IF(OR($K23="",F23=""),"",IF(COUNTIFS($B:$B,$B23,$A:$A,$K23,F:F,">=0")=0,"",F23-SUMIFS(F:F,$B:$B,$B23,$A:$A,$K23))) | O23: =IF(OR($K23="",G23=""),"",IF(COUNTIFS($B:$B,$B23,$A:$A,$K23,G:G,">=0")=0,"",G23-SUMIFS(G:G,$B:$B,$B23,$A:$A,$K23)))
A24: 46324 | B24: Ryzen 5 7500F | C24: CPU | D24: 135.6 | E24: 114.99 | H24: =IFERROR(IF(INDEX(Dólar!$B:$B,MATCH(A24,Dólar!$A:$A,0))="","",INDEX(Dólar!$B:$B,MATCH(A24,Dólar!$A:$A,0))),"") | I24: =IFERROR(INDEX(Dólar!$E:$E,MATCH(A24,Dólar!$A:$A,0)),"") | J24: ver anuncio | K24: 46323 | L24: =IF(OR($K24="",D24=""),"",IF(COUNTIFS($B:$B,$B24,$A:$A,$K24,D:D,">=0")=0,"",D24-SUMIFS(D:D,$B:$B,$B24,$A:$A,$K24))) | M24: =IF(OR($K24="",E24=""),"",IF(COUNTIFS($B:$B,$B24,$A:$A,$K24,E:E,">=0")=0,"",E24-SUMIFS(E:E,$B:$B,$B24,$A:$A,$K24))) | N24: =IF(OR($K24="",F24=""),"",IF(COUNTIFS($B:$B,$B24,$A:$A,$K24,F:F,">=0")=0,"",F24-SUMIFS(F:F,$B:$B,$B24,$A:$A,$K24))) | O24: =IF(OR($K24="",G24=""),"",IF(COUNTIFS($B:$B,$B24,$A:$A,$K24,G:G,">=0")=0,"",G24-SUMIFS(G:G,$B:$B,$B24,$A:$A,$K24)))
A25: 46324 | B25: Ryzen 5 5600 | C25: CPU | D25: 138.9 | E25: 131.99 | H25: =IFERROR(IF(INDEX(Dólar!$B:$B,MATCH(A25,Dólar!$A:$A,0))="","",INDEX(Dólar!$B:$B,MATCH(A25,Dólar!$A:$A,0))),"") | I25: =IFERROR(INDEX(Dólar!$E:$E,MATCH(A25,Dólar!$A:$A,0)),"") | J25: ver anuncio | K25: 46323 | L25: =IF(OR($K25="",D25=""),"",IF(COUNTIFS($B:$B,$B25,$A:$A,$K25,D:D,">=0")=0,"",D25-SUMIFS(D:D,$B:$B,$B25,$A:$A,$K25))) | M25: =IF(OR($K25="",E25=""),"",IF(COUNTIFS($B:$B,$B25,$A:$A,$K25,E:E,">=0")=0,"",E25-SUMIFS(E:E,$B:$B,$B25,$A:$A,$K25))) | N25: =IF(OR($K25="",F25=""),"",IF(COUNTIFS($B:$B,$B25,$A:$A,$K25,F:F,">=0")=0,"",F25-SUMIFS(F:F,$B:$B,$B25,$A:$A,$K25))) | O25: =IF(OR($K25="",G25=""),"",IF(COUNTIFS($B:$B,$B25,$A:$A,$K25,G:G,">=0")=0,"",G25-SUMIFS(G:G,$B:$B,$B25,$A:$A,$K25)))
A26: 46324 | B26: RAM DDR4 16GB (2x8) 3200 | C26: RAM | D26: 89.99 | E26: 59.99 | H26: =IFERROR(IF(INDEX(Dólar!$B:$B,MATCH(A26,Dólar!$A:$A,0))="","",INDEX(Dólar!$B:$B,MATCH(A26,Dólar!$A:$A,0))),"") | I26: =IFERROR(INDEX(Dólar!$E:$E,MATCH(A26,Dólar!$A:$A,0)),"") | J26: ver anuncio | K26: 46323 | L26: =IF(OR($K26="",D26=""),"",IF(COUNTIFS($B:$B,$B26,$A:$A,$K26,D:D,">=0")=0,"",D26-SUMIFS(D:D,$B:$B,$B26,$A:$A,$K26))) | M26: =IF(OR($K26="",E26=""),"",IF(COUNTIFS($B:$B,$B26,$A:$A,$K26,E:E,">=0")=0,"",E26-SUMIFS(E:E,$B:$B,$B26,$A:$A,$K26))) | N26: =IF(OR($K26="",F26=""),"",IF(COUNTIFS($B:$B,$B26,$A:$A,$K26,F:F,">=0")=0,"",F26-SUMIFS(F:F,$B:$B,$B26,$A:$A,$K26))) | O26: =IF(OR($K26="",G26=""),"",IF(COUNTIFS($B:$B,$B26,$A:$A,$K26,G:G,">=0")=0,"",G26-SUMIFS(G:G,$B:$B,$B26,$A:$A,$K26)))
A27: 46324 | B27: Intel Core i5-14400F | C27: CPU | D27: 164.49 | E27: 130 | H27: =IFERROR(IF(INDEX(Dólar!$B:$B,MATCH(A27,Dólar!$A:$A,0))="","",INDEX(Dólar!$B:$B,MATCH(A27,Dólar!$A:$A,0))),"") | I27: =IFERROR(INDEX(Dólar!$E:$E,MATCH(A27,Dólar!$A:$A,0)),"") | J27: ver anuncio | K27: 46323 | L27: =IF(OR($K27="",D27=""),"",IF(COUNTIFS($B:$B,$B27,$A:$A,$K27,D:D,">=0")=0,"",D27-SUMIFS(D:D,$B:$B,$B27,$A:$A,$K27))) | M27: =IF(OR($K27="",E27=""),"",IF(COUNTIFS($B:$B,$B27,$A:$A,$K27,E:E,">=0")=0,"",E27-SUMIFS(E:E,$B:$B,$B27,$A:$A,$K27))) | N27: =IF(OR($K27="",F27=""),"",IF(COUNTIFS($B:$B,$B27,$A:$A,$K27,F:F,">=0")=0,"",F27-SUMIFS(F:F,$B:$B,$B27,$A:$A,$K27))) | O27: =IF(OR($K27="",G27=""),"",IF(COUNTIFS($B:$B,$B27,$A:$A,$K27,G:G,">=0")=0,"",G27-SUMIFS(G:G,$B:$B,$B27,$A:$A,$K27)))
A28: 46324 | B28: Intel Core i5-13400 | C28: CPU | E28: 129.99 | H28: =IFERROR(IF(INDEX(Dólar!$B:$B,MATCH(A28,Dólar!$A:$A,0))="","",INDEX(Dólar!$B:$B,MATCH(A28,Dólar!$A:$A,0))),"") | I28: =IFERROR(INDEX(Dólar!$E:$E,MATCH(A28,Dólar!$A:$A,0)),"") | J28: ver anuncio | K28: 46323 | L28: =IF(OR($K28="",D28=""),"",IF(COUNTIFS($B:$B,$B28,$A:$A,$K28,D:D,">=0")=0,"",D28-SUMIFS(D:D,$B:$B,$B28,$A:$A,$K28))) | M28: =IF(OR($K28="",E28=""),"",IF(COUNTIFS($B:$B,$B28,$A:$A,$K28,E:E,">=0")=0,"",E28-SUMIFS(E:E,$B:$B,$B28,$A:$A,$K28))) | N28: =IF(OR($K28="",F28=""),"",IF(COUNTIFS($B:$B,$B28,$A:$A,$K28,F:F,">=0")=0,"",F28-SUMIFS(F:F,$B:$B,$B28,$A:$A,$K28))) | O28: =IF(OR($K28="",G28=""),"",IF(COUNTIFS($B:$B,$B28,$A:$A,$K28,G:G,">=0")=0,"",G28-SUMIFS(G:G,$B:$B,$B28,$A:$A,$K28)))
A29: 46324 | B29: Intel Core i5-12400F | C29: CPU | D29: 140 | E29: 119.99 | H29: =IFERROR(IF(INDEX(Dólar!$B:$B,MATCH(A29,Dólar!$A:$A,0))="","",INDEX(Dólar!$B:$B,MATCH(A29,Dólar!$A:$A,0))),"") | I29: =IFERROR(INDEX(Dólar!$E:$E,MATCH(A29,Dólar!$A:$A,0)),"") | J29: ver anuncio | K29: 46323 | L29: =IF(OR($K29="",D29=""),"",IF(COUNTIFS($B:$B,$B29,$A:$A,$K29,D:D,">=0")=0,"",D29-SUMIFS(D:D,$B:$B,$B29,$A:$A,$K29))) | M29: =IF(OR($K29="",E29=""),"",IF(COUNTIFS($B:$B,$B29,$A:$A,$K29,E:E,">=0")=0,"",E29-SUMIFS(E:E,$B:$B,$B29,$A:$A,$K29))) | N29: =IF(OR($K29="",F29=""),"",IF(COUNTIFS($B:$B,$B29,$A:$A,$K29,F:F,">=0")=0,"",F29-SUMIFS(F:F,$B:$B,$B29,$A:$A,$K29))) | O29: =IF(OR($K29="",G29=""),"",IF(COUNTIFS($B:$B,$B29,$A:$A,$K29,G:G,">=0")=0,"",G29-SUMIFS(G:G,$B:$B,$B29,$A:$A,$K29)))
A30: 46324 | B30: Intel Core Ultra 7 265K | C30: CPU | D30: 259.99 | E30: 249.99 | H30: =IFERROR(IF(INDEX(Dólar!$B:$B,MATCH(A30,Dólar!$A:$A,0))="","",INDEX(Dólar!$B:$B,MATCH(A30,Dólar!$A:$A,0))),"") | I30: =IFERROR(INDEX(Dólar!$E:$E,MATCH(A30,Dólar!$A:$A,0)),"") | J30: ver anuncio | K30: 46323 | L30: =IF(OR($K30="",D30=""),"",IF(COUNTIFS($B:$B,$B30,$A:$A,$K30,D:D,">=0")=0,"",D30-SUMIFS(D:D,$B:$B,$B30,$A:$A,$K30))) | M30: =IF(OR($K30="",E30=""),"",IF(COUNTIFS($B:$B,$B30,$A:$A,$K30,E:E,">=0")=0,"",E30-SUMIFS(E:E,$B:$B,$B30,$A:$A,$K30))) | N30: =IF(OR($K30="",F30=""),"",IF(COUNTIFS($B:$B,$B30,$A:$A,$K30,F:F,">=0")=0,"",F30-SUMIFS(F:F,$B:$B,$B30,$A:$A,$K30))) | O30: =IF(OR($K30="",G30=""),"",IF(COUNTIFS($B:$B,$B30,$A:$A,$K30,G:G,">=0")=0,"",G30-SUMIFS(G:G,$B:$B,$B30,$A:$A,$K30)))
A31: 46324 | B31: Corsair Vengeance RGB DDR5 32GB (2x16) 6000 | C31: RAM | D31: 450 | E31: 419.99 | H31: =IFERROR(IF(INDEX(Dólar!$B:$B,MATCH(A31,Dólar!$A:$A,0))="","",INDEX(Dólar!$B:$B,MATCH(A31,Dólar!$A:$A,0))),"") | I31: =IFERROR(INDEX(Dólar!$E:$E,MATCH(A31,Dólar!$A:$A,0)),"") | J31: ver anuncio | K31: 46323 | L31: =IF(OR($K31="",D31=""),"",IF(COUNTIFS($B:$B,$B31,$A:$A,$K31,D:D,">=0")=0,"",D31-SUMIFS(D:D,$B:$B,$B31,$A:$A,$K31))) | M31: =IF(OR($K31="",E31=""),"",IF(COUNTIFS($B:$B,$B31,$A:$A,$K31,E:E,">=0")=0,"",E31-SUMIFS(E:E,$B:$B,$B31,$A:$A,$K31))) | N31: =IF(OR($K31="",F31=""),"",IF(COUNTIFS($B:$B,$B31,$A:$A,$K31,F:F,">=0")=0,"",F31-SUMIFS(F:F,$B:$B,$B31,$A:$A,$K31))) | O31: =IF(OR($K31="",G31=""),"",IF(COUNTIFS($B:$B,$B31,$A:$A,$K31,G:G,">=0")=0,"",G31-SUMIFS(G:G,$B:$B,$B31,$A:$A,$K31)))
A32: 46324 | B32: Corsair Vengeance RGB DDR5 32GB (2x16) 5600 | C32: RAM | D32: 459 | E32: 389.99 | H32: =IFERROR(IF(INDEX(Dólar!$B:$B,MATCH(A32,Dólar!$A:$A,0))="","",INDEX(Dólar!$B:$B,MATCH(A32,Dólar!$A:$A,0))),"") | I32: =IFERROR(INDEX(Dólar!$E:$E,MATCH(A32,Dólar!$A:$A,0)),"") | J32: ver anuncio | K32: 46323 | L32: =IF(OR($K32="",D32=""),"",IF(COUNTIFS($B:$B,$B32,$A:$A,$K32,D:D,">=0")=0,"",D32-SUMIFS(D:D,$B:$B,$B32,$A:$A,$K32))) | M32: =IF(OR($K32="",E32=""),"",IF(COUNTIFS($B:$B,$B32,$A:$A,$K32,E:E,">=0")=0,"",E32-SUMIFS(E:E,$B:$B,$B32,$A:$A,$K32))) | N32: =IF(OR($K32="",F32=""),"",IF(COUNTIFS($B:$B,$B32,$A:$A,$K32,F:F,">=0")=0,"",F32-SUMIFS(F:F,$B:$B,$B32,$A:$A,$K32))) | O32: =IF(OR($K32="",G32=""),"",IF(COUNTIFS($B:$B,$B32,$A:$A,$K32,G:G,">=0")=0,"",G32-SUMIFS(G:G,$B:$B,$B32,$A:$A,$K32)))
A33: 46323 | B33: SSD NVMe 2TB | C33: SSD | D33: 185 | E33: 179.99 | H33: =IFERROR(IF(INDEX(Dólar!$B:$B,MATCH(A33,Dólar!$A:$A,0))="","",INDEX(Dólar!$B:$B,MATCH(A33,Dólar!$A:$A,0))),"") | I33: =IFERROR(INDEX(Dólar!$E:$E,MATCH(A33,Dólar!$A:$A,0)),"") | J33: ver anuncio | K33: 46322 | L33: =IF(OR($K33="",D33=""),"",IF(COUNTIFS($B:$B,$B33,$A:$A,$K33,D:D,">=0")=0,"",D33-SUMIFS(D:D,$B:$B,$B33,$A:$A,$K33))) | M33: =IF(OR($K33="",E33=""),"",IF(COUNTIFS($B:$B,$B33,$A:$A,$K33,E:E,">=0")=0,"",E33-SUMIFS(E:E,$B:$B,$B33,$A:$A,$K33))) | N33: =IF(OR($K33="",F33=""),"",IF(COUNTIFS($B:$B,$B33,$A:$A,$K33,F:F,">=0")=0,"",F33-SUMIFS(F:F,$B:$B,$B33,$A:$A,$K33))) | O33: =IF(OR($K33="",G33=""),"",IF(COUNTIFS($B:$B,$B33,$A:$A,$K33,G:G,">=0")=0,"",G33-SUMIFS(G:G,$B:$B,$B33,$A:$A,$K33)))
A34: 46323 | B34: SSD NVMe 1TB | C34: SSD | D34: 114.99 | E34: 85 | F34: 1100 | H34: =IFERROR(IF(INDEX(Dólar!$B:$B,MATCH(A34,Dólar!$A:$A,0))="","",INDEX(Dólar!$B:$B,MATCH(A34,Dólar!$A:$A,0))),"") | I34: =IFERROR(INDEX(Dólar!$E:$E,MATCH(A34,Dólar!$A:$A,0)),"") | J34: ver anuncio | K34: 46322 | L34: =IF(OR($K34="",D34=""),"",IF(COUNTIFS($B:$B,$B34,$A:$A,$K34,D:D,">=0")=0,"",D34-SUMIFS(D:D,$B:$B,$B34,$A:$A,$K34))) | M34: =IF(OR($K34="",E34=""),"",IF(COUNTIFS($B:$B,$B34,$A:$A,$K34,E:E,">=0")=0,"",E34-SUMIFS(E:E,$B:$B,$B34,$A:$A,$K34))) | N34: =IF(OR($K34="",F34=""),"",IF(COUNTIFS($B:$B,$B34,$A:$A,$K34,F:F,">=0")=0,"",F34-SUMIFS(F:F,$B:$B,$B34,$A:$A,$K34))) | O34: =IF(OR($K34="",G34=""),"",IF(COUNTIFS($B:$B,$B34,$A:$A,$K34,G:G,">=0")=0,"",G34-SUMIFS(G:G,$B:$B,$B34,$A:$A,$K34)))
A35: 46323 | B35: Ryzen 9 9950X | C35: CPU | D35: 549.99 | E35: 454.99 | H35: =IFERROR(IF(INDEX(Dólar!$B:$B,MATCH(A35,Dólar!$A:$A,0))="","",INDEX(Dólar!$B:$B,MATCH(A35,Dólar!$A:$A,0))),"") | I35: =IFERROR(INDEX(Dólar!$E:$E,MATCH(A35,Dólar!$A:$A,0)),"") | J35: ver anuncio | K35: 46322 | L35: =IF(OR($K35="",D35=""),"",IF(COUNTIFS($B:$B,$B35,$A:$A,$K35,D:D,">=0")=0,"",D35-SUMIFS(D:D,$B:$B,$B35,$A:$A,$K35))) | M35: =IF(OR($K35="",E35=""),"",IF(COUNTIFS($B:$B,$B35,$A:$A,$K35,E:E,">=0")=0,"",E35-SUMIFS(E:E,$B:$B,$B35,$A:$A,$K35))) | N35: =IF(OR($K35="",F35=""),"",IF(COUNTIFS($B:$B,$B35,$A:$A,$K35,F:F,">=0")=0,"",F35-SUMIFS(F:F,$B:$B,$B35,$A:$A,$K35))) | O35: =IF(OR($K35="",G35=""),"",IF(COUNTIFS($B:$B,$B35,$A:$A,$K35,G:G,">=0")=0,"",G35-SUMIFS(G:G,$B:$B,$B35,$A:$A,$K35)))
A36: 46323 | B36: Ryzen 7 7800X3D | C36: CPU | D36: 325 | E36: 275 | H36: =IFERROR(IF(INDEX(Dólar!$B:$B,MATCH(A36,Dólar!$A:$A,0))="","",INDEX(Dólar!$B:$B,MATCH(A36,Dólar!$A:$A,0))),"") | I36: =IFERROR(INDEX(Dólar!$E:$E,MATCH(A36,Dólar!$A:$A,0)),"") | J36: ver anuncio | K36: 46322 | L36: =IF(OR($K36="",D36=""),"",IF(COUNTIFS($B:$B,$B36,$A:$A,$K36,D:D,">=0")=0,"",D36-SUMIFS(D:D,$B:$B,$B36,$A:$A,$K36))) | M36: =IF(OR($K36="",E36=""),"",IF(COUNTIFS($B:$B,$B36,$A:$A,$K36,E:E,">=0")=0,"",E36-SUMIFS(E:E,$B:$B,$B36,$A:$A,$K36))) | N36: =IF(OR($K36="",F36=""),"",IF(COUNTIFS($B:$B,$B36,$A:$A,$K36,F:F,">=0")=0,"",F36-SUMIFS(F:F,$B:$B,$B36,$A:$A,$K36))) | O36: =IF(OR($K36="",G36=""),"",IF(COUNTIFS($B:$B,$B36,$A:$A,$K36,G:G,">=0")=0,"",G36-SUMIFS(G:G,$B:$B,$B36,$A:$A,$K36)))
A37: 46323 | B37: Ryzen 7 7700X | C37: CPU | D37: 219 | E37: 189.99 | F37: 4000 | H37: =IFERROR(IF(INDEX(Dólar!$B:$B,MATCH(A37,Dólar!$A:$A,0))="","",INDEX(Dólar!$B:$B,MATCH(A37,Dólar!$A:$A,0))),"") | I37: =IFERROR(INDEX(Dólar!$E:$E,MATCH(A37,Dólar!$A:$A,0)),"") | J37: ver anuncio | K37: 46322 | L37: =IF(OR($K37="",D37=""),"",IF(COUNTIFS($B:$B,$B37,$A:$A,$K37,D:D,">=0")=0,"",D37-SUMIFS(D:D,$B:$B,$B37,$A:$A,$K37))) | M37: =IF(OR($K37="",E37=""),"",IF(COUNTIFS($B:$B,$B37,$A:$A,$K37,E:E,">=0")=0,"",E37-SUMIFS(E:E,$B:$B,$B37,$A:$A,$K37))) | N37: =IF(OR($K37="",F37=""),"",IF(COUNTIFS($B:$B,$B37,$A:$A,$K37,F:F,">=0")=0,"",F37-SUMIFS(F:F,$B:$B,$B37,$A:$A,$K37))) | O37: =IF(OR($K37="",G37=""),"",IF(COUNTIFS($B:$B,$B37,$A:$A,$K37,G:G,">=0")=0,"",G37-SUMIFS(G:G,$B:$B,$B37,$A:$A,$K37)))
A38: 46323 | B38: Ryzen 7 5700X3D | C38: CPU | E38: 336 | H38: =IFERROR(IF(INDEX(Dólar!$B:$B,MATCH(A38,Dólar!$A:$A,0))="","",INDEX(Dólar!$B:$B,MATCH(A38,Dólar!$A:$A,0))),"") | I38: =IFERROR(INDEX(Dólar!$E:$E,MATCH(A38,Dólar!$A:$A,0)),"") | J38: ver anuncio | K38: 46322 | L38: =IF(OR($K38="",D38=""),"",IF(COUNTIFS($B:$B,$B38,$A:$A,$K38,D:D,">=0")=0,"",D38-SUMIFS(D:D,$B:$B,$B38,$A:$A,$K38))) | M38: =IF(OR($K38="",E38=""),"",IF(COUNTIFS($B:$B,$B38,$A:$A,$K38,E:E,">=0")=0,"",E38-SUMIFS(E:E,$B:$B,$B38,$A:$A,$K38))) | N38: =IF(OR($K38="",F38=""),"",IF(COUNTIFS($B:$B,$B38,$A:$A,$K38,F:F,">=0")=0,"",F38-SUMIFS(F:F,$B:$B,$B38,$A:$A,$K38))) | O38: =IF(OR($K38="",G38=""),"",IF(COUNTIFS($B:$B,$B38,$A:$A,$K38,G:G,">=0")=0,"",G38-SUMIFS(G:G,$B:$B,$B38,$A:$A,$K38)))
A39: 46323 | B39: Ryzen 5 7600 | C39: CPU | D39: 146.98 | E39: 119 | H39: =IFERROR(IF(INDEX(Dólar!$B:$B,MATCH(A39,Dólar!$A:$A,0))="","",INDEX(Dólar!$B:$B,MATCH(A39,Dólar!$A:$A,0))),"") | I39: =IFERROR(INDEX(Dólar!$E:$E,MATCH(A39,Dólar!$A:$A,0)),"") | J39: ver anuncio | K39: 46322 | L39: =IF(OR($K39="",D39=""),"",IF(COUNTIFS($B:$B,$B39,$A:$A,$K39,D:D,">=0")=0,"",D39-SUMIFS(D:D,$B:$B,$B39,$A:$A,$K39))) | M39: =IF(OR($K39="",E39=""),"",IF(COUNTIFS($B:$B,$B39,$A:$A,$K39,E:E,">=0")=0,"",E39-SUMIFS(E:E,$B:$B,$B39,$A:$A,$K39))) | N39: =IF(OR($K39="",F39=""),"",IF(COUNTIFS($B:$B,$B39,$A:$A,$K39,F:F,">=0")=0,"",F39-SUMIFS(F:F,$B:$B,$B39,$A:$A,$K39))) | O39: =IF(OR($K39="",G39=""),"",IF(COUNTIFS($B:$B,$B39,$A:$A,$K39,G:G,">=0")=0,"",G39-SUMIFS(G:G,$B:$B,$B39,$A:$A,$K39)))
A40: 46323 | B40: Ryzen 5 7500F | C40: CPU | D40: 135.6 | E40: 129.99 | H40: =IFERROR(IF(INDEX(Dólar!$B:$B,MATCH(A40,Dólar!$A:$A,0))="","",INDEX(Dólar!$B:$B,MATCH(A40,Dólar!$A:$A,0))),"") | I40: =IFERROR(INDEX(Dólar!$E:$E,MATCH(A40,Dólar!$A:$A,0)),"") | J40: ver anuncio | K40: 46322 | L40: =IF(OR($K40="",D40=""),"",IF(COUNTIFS($B:$B,$B40,$A:$A,$K40,D:D,">=0")=0,"",D40-SUMIFS(D:D,$B:$B,$B40,$A:$A,$K40))) | M40: =IF(OR($K40="",E40=""),"",IF(COUNTIFS($B:$B,$B40,$A:$A,$K40,E:E,">=0")=0,"",E40-SUMIFS(E:E,$B:$B,$B40,$A:$A,$K40))) | N40: =IF(OR($K40="",F40=""),"",IF(COUNTIFS($B:$B,$B40,$A:$A,$K40,F:F,">=0")=0,"",F40-SUMIFS(F:F,$B:$B,$B40,$A:$A,$K40))) | O40: =IF(OR($K40="",G40=""),"",IF(COUNTIFS($B:$B,$B40,$A:$A,$K40,G:G,">=0")=0,"",G40-SUMIFS(G:G,$B:$B,$B40,$A:$A,$K40)))
...

Sheet Supuestos
A1: Supuestos del cálculo (celdas azules: se pueden cambiar)
A3: Unidades por pedido | B3: 2
A4: Courier B: USD por kg | B4: 28
A5: Courier B: mínimo kg | B5: 1
A6: Courier B: salto kg | B6: 0.5
A7: Caja exterior + relleno, g | B7: 300
A8: Courier A: USD por producto | B8: 10
A9: Courier A: sales tax | B9: 0.07
A10: Aduana boliviana extra (incluida en los couriers) | B10: 0
A11: Dólar para cálculos, Bs/USD | B11: =INDEX(Dólar!$F:$F,MATCH(MAX(Dólar!$A:$A),Dólar!$A:$A,0))
A12: Umbral 'Conviene' | B12: 0.15
A13: Umbral 'Justo' | B13: 0.05
A15: Fuente de los supuestos: CLAUDE.md (couriers del usuario). Dólar: hoja Dólar (BCB y paralelo P2P).

Sheet Dólar
A1: Fecha | B1: Oficial BCB | C1: Paralelo compra | D1: Paralelo venta | E1: Paralelo promedio | F1: Usado en cálculos | G1: Fuente
A2: 46305 | B2: 11.73 | C2: 11.86 | D2: 11.91 | E2: =IF(COUNT(C2:D2)=2,AVERAGE(C2:D2),"") | F2: 11.9 | G2: referencia del usuario (CLAUDE.md)
A3: 46306 | E3: =IF(COUNT(C3:D3)=2,AVERAGE(C3:D3),"") | F3: 11.9 | G3: sin cotización del día: se usó la referencia del 10/10 (estimado)
A4: 46307 | B4: 11.73 | C4: 11.86 | D4: 11.83 | E4: =IF(COUNT(C4:D4)=2,AVERAGE(C4:D4),"") | F4: 11.85 | G4: BCB oficial del 12/10 (Red Uno); paralelo dolarbolivia.net 12/10 08:50 (promedio de 8 plataformas P2P); usado = promedio del paralelo
A5: 46308 | B5: 11.73 | C5: 11.85 | D5: 11.88 | E5: =IF(COUNT(C5:D5)=2,AVERAGE(C5:D5),"") | F5: 11.87 | G5: BCB oficial 11.73; paralelo dolarbolivia.net 13/10 (compra 11.85 / venta 11.88); usado = promedio del paralelo
A6: 46309 | B6: 11.7 | C6: 11.84 | D6: 11.88 | E6: =IF(COUNT(C6:D6)=2,AVERAGE(C6:D6),"") | F6: 11.86 | G6: BCB oficial 11.70; paralelo dolarbolivia.net 14/10 (compra 11.84 / venta 11.88; la página es inconsistente entre compra y venta); usado = promedio del paralelo
A7: 46310 | B7: 11.7 | C7: 11.86 | D7: 11.83 | E7: =IF(COUNT(C7:D7)=2,AVERAGE(C7:D7),"") | F7: 11.85 | G7: BCB oficial 11.70; paralelo dolarbolivia.net 15/10 (compra 11.86 / venta 11.83; la página es inconsistente entre compra y venta); usado = promedio del paralelo
A8: 46311 | B8: 11.68 | C8: 11.83 | D8: 11.79 | E8: =IF(COUNT(C8:D8)=2,AVERAGE(C8:D8),"") | F8: 11.81 | G8: BCB oficial 11.68; paralelo dolarbolivia.net 16/10 (compra 11.83 / venta 11.79; la página es inconsistente entre compra y venta); usado = promedio del paralelo
A9: 46312 | B9: 11.68 | C9: 11.83 | D9: 11.79 | E9: =IF(COUNT(C9:D9)=2,AVERAGE(C9:D9),"") | F9: 11.81 | G9: BCB oficial 11.68; paralelo dolarbolivia.net 17/10 (compra 11.83 / venta 11.79; la página es inconsistente entre compra y venta); usado = promedio del paralelo
A10: 46313 | B10: 11.69 | C10: 11.85 | D10: 11.81 | E10: =IF(COUNT(C10:D10)=2,AVERAGE(C10:D10),"") | F10: 11.83 | G10: BCB oficial 11.69; paralelo dolarbolivia.net 18/10 (compra 11.85 / venta 11.81; la página es inconsistente entre compra y venta); usado = promedio del paralelo
A11: 46314 | B11: 11.69 | C11: 11.83 | D11: 11.8 | E11: =IF(COUNT(C11:D11)=2,AVERAGE(C11:D11),"") | F11: 11.82 | G11: BCB oficial 11.69; paralelo dolarbolivia.net 19/10 11:55 (compra 11.83 / venta 11.80); usado = promedio del paralelo
A12: 46315 | B12: 11.7 | C12: 11.84 | D12: 11.82 | E12: =IF(COUNT(C12:D12)=2,AVERAGE(C12:D12),"") | F12: 11.83 | G12: BCB oficial 11.70 (bcb.gob.bo); paralelo dolarbolivia.net 20/10 07:55 (compra 11.84 / venta 11.82); usado = promedio del paralelo
A13: 46316 | B13: 11.7 | C13: 11.91 | D13: 11.9 | E13: =IF(COUNT(C13:D13)=2,AVERAGE(C13:D13),"") | F13: 11.91 | G13: BCB oficial 11.70 (dolarbolivia.net 21/10 11:54); paralelo dolarbolivia.net 21/10 (compra 11.91 / venta 11.90); usado = promedio del paralelo
A14: 46317 | B14: 11.73 | C14: 11.91 | D14: 11.88 | E14: =IF(COUNT(C14:D14)=2,AVERAGE(C14:D14),"") | F14: 11.9 | G14: BCB oficial 11.73 (dolarbolivia.net 22/10 07:55); paralelo dolarbolivia.net 22/10 (compra 11.91 / venta 11.88); usado = promedio del paralelo
A15: 46318 | B15: 11.75 | C15: 11.94 | D15: 11.92 | E15: =IF(COUNT(C15:D15)=2,AVERAGE(C15:D15),"") | F15: 11.93 | G15: BCB oficial 11.75 (dolarbolivia.net 23/10 07:54); paralelo dolarbolivia.net 23/10 (compra 11.94 / venta 11.92); usado = promedio del paralelo
... A21: 46324 | B21: 12.02 | C21: 12.16 | D21: 12.14 | E21: =IF(COUNT(C21:D21)=2,AVERAGE(C21:D21),"") | F21: 12.2 | G21: Oficial y paralelo del 28/10 (dolarbolivia.net; no hallé el de hoy); USDT CriptoYa (Binance P2P) 29/10 07:56 BOT, usado = USDT para comprar; CriptoYa USDT, nube 29/10; USDT CriptoYa (Binance P2P) 07:57 BOT (comprar 12.2 / vender 12.16), usado = USDT para comprar
A22: 46325 | E22: =IF(COUNT(C22:D22)=2,AVERAGE(C22:D22),"") | F22: 11.98 | G22: USDT CriptoYa (Binance P2P) 10:36 BOT (comprar 11.98 / vender 11.95), usado = USDT para comprar

Sheet Movimientos
A1: Fecha | B1: Origen | C1: Producto | D1: Condición / vendedor | E1: Precio | F1: Moneda | G1: Detalle | H1: Link
A2: 46307 | B2: eBay | C2: Ryzen 5 5600 | D2: nuevo | E2: 159.99 | F2: USD | G2: eBay vía Chrome, vendedor en EE.UU. (PC de la casa); envío gratis | H2: ver
A3: 46307 | B3: eBay | C3: Ryzen 5 5600 | D3: usado | E3: 124.68 | F3: USD | G3: eBay vía Chrome, vendedor en EE.UU. (PC de la casa) | H3: ver
A4: 46307 | B4: eBay | C4: Ryzen 7 5700X3D | D4: usado | E4: 305.79 | F4: USD | G4: eBay vía Chrome, vendedor en EE.UU. (PC de la casa); no hay nuevos de vendedores de EE.UU. | H4: ver
A5: 46307 | B5: eBay | C5: Ryzen 5 7600 | D5: nuevo | E5: 137.04 | F5: USD | G5: eBay vía Chrome, vendedor en EE.UU. (PC de la casa); tray/OEM; en caja USD 240,53 | H5: ver
A6: 46307 | B6: eBay | C6: Ryzen 5 7600 | D6: usado | E6: 120.99 | F6: USD | G6: eBay vía Chrome, vendedor en EE.UU. (PC de la casa) | H6: ver
A7: 46307 | B7: eBay | C7: Ryzen 7 7800X3D | D7: nuevo | E7: 320 | F7: USD | G7: eBay vía Chrome, vendedor en EE.UU. (PC de la casa); envío gratis | H7: ver
A8: 46307 | B8: eBay | C8: Ryzen 7 7800X3D | D8: usado | E8: 282.52 | F8: USD | G8: eBay vía Chrome, vendedor en EE.UU. (PC de la casa) | H8: ver
A9: 46307 | B9: eBay | C9: Ryzen 9 9950X | D9: nuevo | E9: 512.1 | F9: USD | G9: eBay vía Chrome, vendedor en EE.UU. (PC de la casa) | H9: ver
A10: 46307 | B10: eBay | C10: Ryzen 9 9950X | D10: usado | E10: 410 | F10: USD | G10: eBay vía Chrome, vendedor en EE.UU. (PC de la casa) | H10: ver
A11: 46307 | B11: eBay | C11: Intel Core i5-12400F | D11: nuevo | E11: 159.95 | F11: USD | G11: eBay vía Chrome, vendedor en EE.UU. (PC de la casa); en caja, envío gratis | H11: ver
A12: 46307 | B12: eBay | C12: Intel Core i5-12400F | D12: usado | E12: 124.99 | F12: USD | G12: eBay vía Chrome, vendedor en EE.UU. (PC de la casa) | H12: ver
A13: 46307 | B13: eBay | C13: Intel Core i5-13400 | D13: nuevo | E13: 259.78 | F13: USD | G13: eBay vía Chrome, vendedor en EE.UU. (PC de la casa); tray/OEM; pocos anuncios | H13: ver
... A594: 46307 | B594: Tienda | C594: Intel Core Ultra 7 265K | D594: Viadata Computadoras (WhatsApp) | E594: 5200 | F594: Bs | G594: nuevo en caja (es el 265KF, sin gráficos integrados; solo referencia; no cuenta) | H594: ver
A595: 46308 | B595: Tienda | C595: Ryzen 7 7800X3D | D595: OverCity (WhatsApp) | E595: 5500 | F595: Bs | G595: nuevo OEM (solo el chip)
A596: 46308 | B596: Tienda | C596: Intel Core i5-14400F | D596: OverCity (WhatsApp) | E596: 2460 | F596: Bs | G596: nuevo OEM
A597: 46308 | B597: Tienda | C597: Intel Core i5-14400F | D597: Soft Computers (WhatsApp) | E597: 2500 | F597: Bs | G597: nuevo OEM
A598: 46308 | B598: Tienda | C598: Corsair Vengeance RGB DDR5 32GB (2x16) 6000 | D598: OverCity (WhatsApp) | E598: 6840 | F598: Bs | G598: nuevo (XPG Lancer RGB 32GB 2x16 6000 CL30: otra marca; no cuenta; Corsair agotada; garantía 3 meses)
A599: 46308 | B599: Marketplace | C599: Ryzen 7 7800X3D | D599: Marketplace Cochabamba (particular/vendedor; Messenger) | E599: 4800 | F599: Bs | G599: nuevo sellado de fábrica, confirmado por el vendedor (último en stock; precio ya rebajado) | H599: ver
A600: 46308 | B600: Tienda | C600: Ryzen 7 7800X3D | D600: OverCity (WhatsApp) | E600: 5350 | F600: Bs | G600: nuevo en caja sellada (box; el OEM está a Bs 5.500; el i5-14400F Bs 2.460 es su precio mínimo)
A601: 46309 | B601: Marketplace | C601: Corsair Vengeance RGB DDR5 32GB (2x16) 5600 | D601: Marketplace Cochabamba | E601: 7400 | F601: Bs | G601: no indicado (Kingston Fury Beast DDR5 32GB 5600: otra marca; solo referencia; no cuenta) | H601: ver
A602: 46309 | B602: Tienda | C602: Intel Core i5-14400F | D602: Geek Store Bolivia (web) | E602: 2953 | F602: Bs | G602: disponible (web; es el i5-14400 con gráficos, no el F; precio USD 249 en la web, a Bs 11,86; solo referencia; no cuenta) | H602: ver
A603: 46309 | B603: Tienda | C603: Intel Core i9-14900K | D603: Crazy Store (WhatsApp) | E603: 6013 | F603: Bs | G603: nuevo (no está en vigilar.csv; USD 499 o Bs 6.013, rebaja ofrecida hasta Bs 5.700; solo referencia; no cuenta)
A604: 46310 | B604: Tienda | C604: Ryzen 7 7800X3D | D604: SMART CUBE (WhatsApp) | E604: 5890 | F604: Bs | G604: nuevo sellado, facturado; llevando 2 rebajan Bs 50 c/u (Bs 5.840)
A605: 46310 | B605: Tienda | C605: Intel Core i5-14400F | D605: SMART CUBE (WhatsApp) | E605: 3080 | F605: Bs | G605: nuevo sellado; llevando 2 rebajan Bs 50 c/u (Bs 3.030)
A606: 46310 | B606: Tienda | C606: RAM DDR5 16GB 6000 (Apacer NOX) | D606: SMART CUBE (WhatsApp) | E606: 3650 | F606: Bs | G606: nuevo (Apacer NOX DDR5 16GB 6000: otra marca y capacidad; solo referencia; no cuenta)
A607: 46310 | B607: Tienda | C607: RAM DDR5 16GB | D607: PC Factor (WhatsApp) | E607: 3792 | F607: Bs | G607: nuevo (USD 320 c/u a Bs 11,85; marca y velocidad por confirmar; solo referencia; no cuenta)
A608: 46310 | B608: Tienda | C608: Ryzen 5 7600 | D608: OverCity (WhatsApp) | E608: 2800 | F608: Bs | G608: OEM
A609: 46310 | B609: Tienda | C609: Intel Core i5-12400F | D609: T&T Todo en Tecnología (WhatsApp) | E609: 2260 | F609: Bs | G609: OEM con cooler Intel; Bs 20 menos c/u llevando 2
A610: 46310 | B610: Tienda | C610: Intel Core i5-14400F | D610: T&T Todo en Tecnología (WhatsApp) | E610: 2750 | F610: Bs | G610: OEM con cooler Intel; Bs 20 menos c/u llevando 2
A611: 46310 | B611: Tienda | C611: Ryzen 7 7700X | D611: Geek Store Bolivia (WhatsApp) | E611: 3480 | F611: Bs | G611: sin confirmar si es sellado (se preguntó)
A612: 46310 | B612: Tienda | C612: Kingston Fury DDR5 16GB (1 módulo) | D612: Geek Store Bolivia (WhatsApp) | E612: 2900 | F612: Bs | G612: otra marca; velocidad por confirmar (no es la Corsair 32GB 2x16)
A613: 46310 | B613: Tienda | C613: SSD NVMe 1TB | D613: Shopping PC (catálogo PDF) | E613: 1754 | F613: Bs | G613: nuevo (Kingston NV3 1TB; lista mayorista USD 148 del 12/10, sin factura; 146 en stock)
A614: 46310 | B614: Tienda | C614: Intel Core i5-14400F | D614: Shopping PC (catálogo PDF) | E614: 2785 | F614: Bs | G614: nuevo en caja (es el i5-14400 BOX con gráficos, no el F; lista mayorista USD 235, sin factura; solo referencia; no cuenta)
... A617: 46311 | B617: Tienda | C617: Intel Core i5-14400F | D617: Soft Computers (WhatsApp) | E617: 2500 | F617: Bs | G617: nuevo OEM; mismo precio por unidad llevando 2
A618: 46311 | B618: Marketplace | C618: SSD NVMe 1TB | D618: Marketplace Cochabamba | E618: 1730 | F618: Bs | G618: nuevo (M.2 1TB, marca no indicada; publicado hace 2 días) | H618: ver
A619: 46311 | B619: Tienda | C619: Intel Core i5-14400F | D619: Cyrex Store (web) | E619: 2384 | F619: Bs | G619: nuevo OEM (web: USD 202 a la tasa de la tienda, 11,80; hay otra publicación del mismo a USD 215) | H619: ver
A620: 46311 | B620: Tienda | C620: Ryzen 7 7800X3D | D620: Cyrex Store (web) | E620: 5664 | F620: Bs | G620: nuevo BOX (web: USD 480 a 11,80) | H620: ver
A621: 46311 | B621: Tienda | C621: Intel Core i5-13400 | D621: Cyrex Store (web) | E621: 2218 | F621: Bs | G621: nuevo OEM (web: es el i5-13400F, sin gráficos; USD 188 a 11,80; solo referencia; no cuenta) | H621: ver
A622: 46311 | B622: Tienda | C622: Ryzen 5 7600 | D622: Punto Tecnológico (WhatsApp) | E622: 2850 | F622: Bs | G622: nuevo OEM, garantía 6 meses (cotización por WhatsApp)
...
